<?xml version="1.0"?>
<robot name="gustav" model="volvo_ec240cl">

    <material name="blue">
        <color rgba="0.0 0.0 1 0.7"/>
    </material>
    <material name="green">
        <color rgba="0.0 0.4 0 0.5"/>
    </material>

    <!-- <track max_speed="0.87" /> -->

    <!-- world link -->
    <link name="base"/>

    <!-- base_link and its fixed joint -->
    <joint name="undercarriage_joint" type="fixed">
        <parent link="base"/>
        <child link="undercarriage"/>
        <origin xyz="0 0 0" rpy="0 0 0"/>
    </joint>

    <link name="undercarriage">
        <visual>
            <origin xyz="0 0 0.05"/>
            <geometry>
                <box size="5.0 4.0 0.1"/>
            </geometry>
            <material name="base_color">
                <color rgba="0.4 0.4 0.4 1.0"/>
            </material>
        </visual>
        <!-- <visual>
            <geometry>
                <mesh filename="package:///home/yorick/Downloads/volvo_undercarage.obj/617afeb7-bd47-42cd-880a-2037f2365277.obj"/>
            </geometry>

            <material name="light_blue">
                <color rgba="0.490 0.490 0.490 1"/>
             </material>
        </visual> -->
    </link>

    <!-- TODO: frame_joint is continuous -->
    <joint name="frame_joint" type="revolute">
        <parent link="undercarriage"/>
        <child link="frame"/>
        <origin xyz="0 0 1.085" rpy="0 0 0"/>
        <axis xyz="0 0 1"/>
        <power coefficient="5" lower="0.02" upper="32767" />
        <limit lower="0" upper="6.283" velocity="0.5"/>
    </joint>

    <link name="frame">
        <!-- <visual>
            <geometry>
                <box size="0.1 0.1 1.0"/>
            </geometry>
            <material name="blue"/>
        </visual> -->
        <!-- <visual>
            <geometry>
                <mesh filename="package:///home/yorick/Downloads/volo_frame.obj/63c51b54-ee9b-4f30-8d95-73b928d979de.obj"/>
            </geometry>

            <material name="light_blue">
                <color rgba="0.929 0.803 0.027 1.0"/>
             </material>
        </visual> -->
    </link>

    <joint name="boom_joint" type="revolute">
        <parent link="frame"/>
        <child link="boom"/>
        <origin xyz="0.16 0 0" rpy="0 0 0" />
        <axis xyz="0 1 0"/>
        <!-- Bound are not correct -->
        <limit effort="1000.0" lower="-1.047" upper="0.785" velocity="0.5"/>
    </joint>

    <link name="boom">
        <!-- <inertial>
            <mass value="500"/>
        </inertial> -->
        <visual>
            <origin xyz="0 0 3.0"/>
            <geometry>
                <box size="0.35 0.35 6.0"/>
            </geometry>
            <material name="blue"/>
        </visual>
        <!-- <visual>
            <origin xyz="0 0 3" rpy="0 0 0"/>
            <geometry>
                <mesh filename="package:///home/yorick/Downloads/volvo_boom.obj/5c04902c-b8ee-47d7-aaa8-ffd69546bdf6.obj"/>
            </geometry>
            
            <material name="blue">
                <color rgba="0.490 0.490 0.490 1"/>
            </material>
        </visual> -->

        <!-- <collision>
            <origin xyz="0 0 3" rpy="0 0 0"/>
            <geometry>
                <box size="0.45 0.45 6"/>
            </geometry>
        </collision> -->
    </link>

    <joint name="arm_joint" type="revolute">
        <parent link="boom"/>
        <child link="arm"/>
        <origin xyz="6 0 0" rpy="0 0 0"/>
        <axis xyz="0 1 0"/>
        <limit effort="1000.0" lower="0.698" upper="2.1" velocity="0.5"/>
    </joint>

    <link name="arm">
        <visual>
            <origin xyz="0 0 1.485"/>
            <geometry>
                <box size="0.35 0.35 2.97"/>
            </geometry>
            <material name="blue"/>
        </visual>
        <!-- <visual>
            <origin xyz="0 0 1.485"/>
            <geometry>
                <mesh filename="package:///home/yorick/Downloads/volvo_arm.obj/be8acb75-fa50-4c48-850e-59a523e38074.obj"/>
            </geometry>
            <material name="white">
                <color rgba="0.811 0.811 0.811 1"/>
            </material>
        </visual> -->
    </link>

    <joint name="attachment_joint" type="revolute">
        <parent link="arm"/>
        <child link="attachment"/>
        <origin xyz="2.97 0 0"/>
        <axis xyz="0 1 0"/>
    </joint>

    <link name="attachment">
        <visual>
            <!-- <origin xyz="0 0 -0.17"/> -->
            <geometry>
                <sphere radius="0.1"/>
            </geometry>
            <material name="green"/>
        </visual>
        <!-- <visual>
            <origin xyz="0 0 0.475"/>
            <geometry>
                <mesh filename="package:///home/yorick/Downloads/volvo_bucket.obj/a4bab2b3-0c61-4fb3-a9de-315b2824320a.obj"/>
            </geometry>
            <material name="red">
                <color rgba="0.929 0.803 0.027 1.0"/>
            </material>
        </visual> -->

        <!-- <collision>
            <geometry>
                <mesh filename="package:///home/yorick/Downloads/volvo_bucket.obj/a4bab2b3-0c61-4fb3-a9de-315b2824320a.obj"/>
            </geometry>
        </collision> -->
    </link>

</robot>
